<?xml version="1.0"?>
<robot name="spot_gripper" xmlns:xacro="http://www.ros.org/wiki/xacro">

  <link name="arm_link_wr0">
    <visual>
      <origin xyz="0 0 0" rpy="0 0 0" />
      <geometry>
        <mesh filename="package://spot_arm/meshes/arm/visual/arm_link_wr0.obj" />
      </geometry>
      <material name="arm_link_wr0">
        <color rgba="0.2 0.2 0.2 1" />
      </material>
    </visual>
    <collision>
      <geometry>
        <mesh filename="package://spot_arm/meshes/arm/collision/arm_link_wr0.obj" />
      </geometry>
    </collision>
    <inertial>
      <origin rpy="-0.4951534907966386 0.0033720434077784134 0.020027599337697932"
        xyz="0.008210677653551102 -0.012051000259816647 3.143483627354726e-05" />
      <mass value="0.98" />
      <inertia ixx="0.0009851320696685427" ixy="0.0" ixz="0.0" iyy="0.0008916145765810678"
        iyz="0.0" izz="0.0012354892751854467" />
    </inertial>
  </link>

  <link name="arm_link_wr1">
    <visual>
      <origin xyz="0 0 0" rpy="0 0 0" />
      <geometry>
        <mesh filename="package://spot_arm/meshes/arm/visual/arm_link_wr1.obj" />
      </geometry>
      <material name="arm_link_wr1">
        <color rgba="0.2 0.2 0.2 1" />
      </material>
    </visual>
    <collision>
      <geometry>
        <mesh filename="package://spot_arm/meshes/arm/collision/arm_link_wr1.obj" />
      </geometry>
    </collision>
    <collision>
      <geometry>
        <mesh filename="package://spot_arm/meshes/arm/collision/front_jaw.obj" />
      </geometry>
    </collision>
    <collision>
      <geometry>
        <mesh filename="package://spot_arm/meshes/arm/collision/middle_jaw.obj" />
      </geometry>
    </collision>
    <collision>
      <geometry>
        <mesh filename="package://spot_arm/meshes/arm/collision/jaw_tooth.obj" />
      </geometry>
    </collision>
    <inertial>
      <origin rpy="0.006393076449033863 0.2928526604761865 -0.022814984050994802"
        xyz="0.12516802549362183 0.00010137435310753062 -0.013997982256114483" />
      <mass value="0.785" />
      <inertia ixx="0.00076741362048185" ixy="0.0" ixz="0.0" iyy="0.0017628124054271809" iyz="0.0"
        izz="0.0016818105865345951" />
    </inertial>
  </link>

  <joint name="arm_wr1" type="revolute">
    <origin xyz="0.0 0.0 0.0" rpy="0 0 0" />
    <axis xyz="1 0 0" />
    <parent link="arm_link_wr0" />
    <child link="arm_link_wr1" />
    <limit effort="30.3" velocity="10.0" lower="-2.87979326579064354163"
      upper="2.87979326579064354163" />
  </joint>

  <link name="arm_link_fngr">
    <visual>
      <origin xyz="0 0 0" rpy="0 0 0" />
      <geometry>
        <mesh filename="package://spot_arm/meshes/arm/visual/arm_link_fngr.obj" />
      </geometry>
      <material name="arm_link_fngr">
        <color rgba="0.2 0.2 0.2 1" />
      </material>
    </visual>
    <collision>
      <geometry>
        <mesh filename="package://spot_arm/meshes/arm/collision/left_hinge.obj" />
      </geometry>
    </collision>
    <collision>
      <geometry>
        <mesh filename="package://spot_arm/meshes/arm/collision/left_finger.obj" />
      </geometry>
    </collision>
    <collision>
      <geometry>
        <mesh filename="package://spot_arm/meshes/arm/collision/left_tooth.obj" />
      </geometry>
    </collision>
    <collision>
      <geometry>
        <mesh filename="package://spot_arm/meshes/arm/collision/right_hinge.obj" />
      </geometry>
    </collision>
    <collision>
      <geometry>
        <mesh filename="package://spot_arm/meshes/arm/collision/right_finger.obj" />
      </geometry>
    </collision>
    <collision>
      <geometry>
        <mesh filename="package://spot_arm/meshes/arm/collision/right_tooth.obj" />
      </geometry>
    </collision>
    <inertial>
      <origin rpy="0.0003416659657240473 0.3751670012784243 -0.004058661249495721"
        xyz="0.04787873849272728 -0.00020676758140325546 -0.01628788933157921" />
      <mass value="0.2" />
      <inertia ixx="0.0001439963634171048" ixy="0.0" ixz="0.0" iyy="0.0003007126997998294"
        iyz="0.0" izz="0.0003912783268020657" />
    </inertial>
  </link>

  <joint name="arm_f1x" type="revolute">
    <origin xyz="0.11745 0 0.014820" rpy="0 -1.5707963267948966 0" />
    <axis xyz="0.0 1.0 0.0" />
    <parent link="arm_link_wr1" />
    <child link="arm_link_fngr" />
    <limit effort="15.32" velocity="10.0" lower="-1.57" upper="1.57" />
  </joint>
</robot>
