<?xml version="1.0" ?>
<!-- =================================================================================== -->
<!-- |    This document was autogenerated by xacro from robot.xacro                    | -->
<!-- |    EDITING THIS FILE BY HAND IS NOT RECOMMENDED ~ eu mexi :p                    | -->
<!-- =================================================================================== -->
<robot name="gripper_description">

  <link name="gripperStator">
      <visual>
          <geometry>
              <mesh filename="package://z1/meshes/visual/z1_GripperStator.dae" scale="1 1 1"/>
          </geometry>
      </visual>
      <collision>
          <geometry>
             <mesh filename="package://z1/meshes/collision/z1_GripperStator.STL" scale="1 1 1"/>
          </geometry>
      </collision>
      <inertial>
          <origin rpy="0 0 0" xyz="0.04764427 -0.00035819 -0.00249162"/>
          <mass value="0.2603655"/>
          <inertia
              ixx="0.00038683" ixy="-0.00000359" ixz="0.00007662"
              iyy="0.00068614" iyz="0.00000209"
              izz="0.00066293"/>
      </inertial>
  </link>

  <link name="gripperMover">
      <visual>
          <geometry>
              <mesh filename="package://z1/meshes/visual/z1_GripperMover.dae" scale="1 1 1"/>
          </geometry>
      </visual>
      <collision>
         <geometry>
              <mesh filename="package://z1/meshes/collision/z1_GripperMover.STL" scale="1 1 1"/>
          </geometry>
      </collision>
      <inertial>
          <origin rpy="0 0 0" xyz="0.01320633 0.00476708 0.00380534"/>
          <mass value="0.27621302"/>
          <inertia
              ixx="0.00017716" ixy="0.00001683" ixz="-0.00001786"
              iyy="0.00026787" iyz="0.00000262"
              izz="0.00035728"/> 
      </inertial>
  </link>

  <joint name="jointGripper" type="revolute">
      <origin rpy="0 -1.5707963267948966 0" xyz="0.049 0.0 0"/>
      <parent link="gripperStator"/>
      <child link="gripperMover"/>
      <axis xyz="0 1 0"/>
      <dynamics damping="1.0" friction="1.0"/>
      <limit effort="30.0" velocity="3.1415" lower="-1.5707963267948966" upper="0.0"/>
  </joint>

</robot>

